Workbook

Sheet Parameters
A1: TEGR Jacobian — Relativistic Particle Dynamics in Teleparallel Equivalent of General Relativity
A2: Physical Constants (Geometrized Units: G = c = 1)
A3: G — Gravitational constant | B3: 1 | C3: dimensionless | D3: Geometric units G = 1
A4: c — Speed of light | B4: 1 | C4: dimensionless | D4: Geometric units c = 1
A5: M — Central (source) mass | B5: 0.01 | C5: geometric mass [m] | D5: M/r₀ = 0.01 → weak-field regime
A6: m — Test-particle mass | B6: 1 | C6: geometric mass [m] | D6: Geodesic independent of m; retained for completeness
A7: Evaluation Point — Coordinates x^μ = (t₀, x₀, y₀, z₀)
A8: t₀ — Coordinate time | B8: 0 | C8: geometric time [m] | D8: Arbitrary for static background
A9: x₀ — x-position | B9: 1 | C9: geometric length [m] | D9: Particle on positive x-axis (r₀ = x₀)
A10: y₀ — y-position | B10: 0 | C10: geometric length [m] | D10: Equatorial plane
A11: z₀ — z-position | B11: 0 | C11: geometric length [m] | D11: Equatorial plane
A12: Derived Radial Quantities
A13: r₀ — Radial distance | B13: =SQRT(B9^2+B10^2+B11^2) | C13: geometric length [m] | D13: r₀ = √(x₀²+y₀²+z₀²)
A14: v — Circular-orbit speed | B14: =SQRT(B3*B5/B13) | C14: dimensionless (c = 1) | D14: Newtonian: v = √(GM/r₀)
A15: γ — Lorentz factor | B15: =1/SQRT(1-B14^2) | C15: dimensionless | D15: γ = 1/√(1−v²)
A16: Evaluation Point — Four-Velocity Components u^μ = dx^μ/dτ
A17: u^t = dt/dτ | B17: =B15 | C17: dimensionless | D17: Lorentz factor γ (circular orbit)
A18: u^x = dx/dτ | B18: 0 | C18: dimensionless | D18: Zero at apoapsis (tangential velocity)
A19: u^y = dy/dτ | B19: =B15*B14 | C19: dimensionless | D19: Tangential: u^y = γ·v
A20: u^z = dz/dτ | B20: 0 | C20: dimensionless | D20: Equatorial plane
A21: Gravitational Potential Φ = −GM/r and Partial Derivatives at (x₀,y₀,z₀)
A22: Φ₀ — Potential | B22: =-B3*B5/B13 | C22: dimensionless | D22: Φ = −GM/r
A23: Φ_x = ∂Φ/∂x | B23: =B3*B5*B9/B13^3 | C23: 1/[m] | D23: =GMx/r³
A24: Φ_y = ∂Φ/∂y | B24: =B3*B5*B10/B13^3 | C24: 1/[m] | D24: =GMy/r³
A25: Φ_z = ∂Φ/∂z | B25: =B3*B5*B11/B13^3 | C25: 1/[m] | D25: =GMz/r³
A26: Φ_xx = ∂²Φ/∂x² | B26: =B3*B5*(B13^2-3*B9^2)/B13^5 | C26: 1/[m²] | D26: =GM(r²−3x²)/r⁵ → −2M/r₀³ at x₀=r₀
A27: Φ_yy = ∂²Φ/∂y² | B27: =B3*B5*(B13^2-3*B10^2)/B13^5 | C27: 1/[m²] | D27: =GM(r²−3y²)/r⁵ → +M/r₀³ at y₀=0
A28: Φ_zz = ∂²Φ/∂z² | B28: =B3*B5*(B13^2-3*B11^2)/B13^5 | C28: 1/[m²] | D28: =GM(r²−3z²)/r⁵ → +M/r₀³ at z₀=0
A29: Φ_xy = ∂²Φ/∂x∂y | B29: =-3*B3*B5*B9*B10/B13^5 | C29: 1/[m²] | D29: =−3GMxy/r⁵
A30: Φ_xz = ∂²Φ/∂x∂z | B30: =-3*B3*B5*B9*B11/B13^5 | C30: 1/[m²] | D30: =−3GMxz/r⁵
A31: Φ_yz = ∂²Φ/∂y∂z | B31: =-3*B3*B5*B10*B11/B13^5 | C31: 1/[m²] | D31: =−3GMyz/r⁵
A32: TEGR Torsion Scalar T = −4GM/r³ and Partial Derivatives at (x₀,y₀,z₀)
A33: T₀ — Torsion scalar | B33: =-4*B3*B5/B13^3 | C33: 1/[m²] | D33: Leading weak-field torsion scalar for diagonal tetrad
A34: Ṫ₀ = dT/dτ at eval point | B34: =B37*B18+B38*B19+B39*B20 | C34: 1/[m²·s] | D34: =T_x·u^x + T_y·u^y + T_z·u^z (zero for tangential orbit)
A35: T_x = ∂T/∂x | B35: =12*B3*B5*B9/B13^5 | C35: 1/[m³] | D35: =12GMx/r⁵
A36: T_y = ∂T/∂y | B36: =12*B3*B5*B10/B13^5 | C36: 1/[m³] | D36: =12GMy/r⁵
A37: T_z = ∂T/∂z | B37: =12*B3*B5*B11/B13^5 | C37: 1/[m³] | D37: =12GMz/r⁵
A38: T_xx = ∂²T/∂x² | B38: =12*B3*B5*(B13^2-5*B9^2)/B13^7 | C38: 1/[m⁴] | D38: =12GM(r²−5x²)/r⁷ → −48M/r₀⁵ at x₀=r₀
A39: T_yy = ∂²T/∂y² | B39: =12*B3*B5*(B13^2-5*B10^2)/B13^7 | C39: 1/[m⁴] | D39: =12GM(r²−5y²)/r⁷ → +12M/r₀⁵ at y₀=0
A40: T_zz = ∂²T/∂z² | B40: =12*B3*B5*(B13^2-5*B11^2)/B13^7 | C40: 1/[m⁴] | D40: =12GM(r²−5z²)/r⁷ → +12M/r₀⁵ at z₀=0
...

Sheet Tetrad
A1: TEGR Diagonal Tetrad e^a_{μ} — Weak-Field Isotropic Schwarzschild (geometrized units, evaluated at (x₀,y₀,z₀))
A2: Tetrad Scalar Functions at Evaluation Point
A3: A = √(1+2Φ₀) — time lapse | B3: =SQRT(1+2*Parameters!B22) | C3: dimensionless | D3: e^(0)_t = A (temporal tetrad component)
A4: B = √(1−2Φ₀) — spatial scale | B4: =SQRT(1-2*Parameters!B22) | C4: dimensionless | D4: e^(i)_i = B (diagonal spatial tetrad components)
A5: A⁻¹ = inverse time lapse | B5: =1/B3 | C5: dimensionless | D5: e_(0)^t = 1/A (inverse tetrad)
A6: B⁻¹ = inverse spatial scale | B6: =1/B4 | C6: dimensionless | D6: e_(i)^i = 1/B (inverse tetrad)
A7: Tetrad Matrix e^a_{μ} (rows = local-frame index a = 0,1,2,3; columns = coord index μ = t,x,y,z)
B8: μ = t | C8: μ = x | D8: μ = y | E8: μ = z | G8: Note
A9: a = 0 (time) | B9: =B3 | C9: 0 | D9: 0 | E9: 0
A10: a = 1 (x) | B10: 0 | C10: =B4 | D10: 0 | E10: 0
A11: a = 2 (y) | B11: 0 | C11: 0 | D11: =B4 | E11: 0
A12: a = 3 (z) | B12: 0 | C12: 0 | D12: 0 | E12: =B4
A13: Inverse Tetrad e_{a}^{μ} (satisfies e^a_{μ} e_{a}^{ν} = δ^ν_μ)
B14: μ = t | C14: μ = x | D14: μ = y | E14: μ = z | G14: Note
A15: a = 0 (time) | B15: =B5 | C15: 0 | D15: 0 | E15: 0
A16: a = 1 (x) | B16: 0 | C16: =B6 | D16: 0 | E16: 0
A17: a = 2 (y) | B17: 0 | C17: 0 | D17: =B6 | E17: 0
A18: a = 3 (z) | B18: 0 | C18: 0 | D18: 0 | E18: =B6
A19: Torsion Scalar T (from tetrad — leading weak-field expression)
A20: T₀ = −4GM/r³ | B20: =Parameters!B33 | C20: 1/[m²] | D20: For diagonal tetrad: T = −4(A′/A)²(1+2Ar) to leading order → −4GM/r³
A21: Verification: Φ₀ check | B21: =Parameters!B22 | C21: dimensionless | D21: Should equal −GM/r₀ = −M/r₀

Sheet Connections
A1: TEGR Weitzenböck Connection Coefficients Γ^ρ_{μν} = e^ρ_a ∂_μ e^a_ν — Relevant Non-Zero Components at Evaluation Point
A2: In the weak-field limit the Weitzenböck connection coincides with the Levi-Civita (Christoffel) connection to first order in Φ. Non-zero components listed below.
A3: Symbol | B3: Formula (Excel) | C3: Value at eval point | E3: Physical meaning
A4: Γ^t_{tx} = Γ^t_{xt} | B4: =Parameters!B23 | D4: ∂Φ/∂x = GMx/r³ — time-position mixing (x)
A5: Γ^t_{ty} = Γ^t_{yt} | B5: =Parameters!B24 | D5: ∂Φ/∂y = GMy/r³ — time-position mixing (y)
A6: Γ^t_{tz} = Γ^t_{zt} | B6: =Parameters!B25 | D6: ∂Φ/∂z = GMz/r³ — time-position mixing (z)
A7: Γ^x_{tt} | B7: =Parameters!B23 | D7: ∂Φ/∂x — gravitoelectric acceleration (x)
A8: Γ^x_{xx} | B8: =-Parameters!B23 | D8: −∂Φ/∂x — self-diagonal spatial
A9: Γ^x_{yy} | B9: =Parameters!B23 | D9: ∂Φ/∂x — off-diagonal spatial y-y
A10: Γ^x_{zz} | B10: =Parameters!B23 | D10: ∂Φ/∂x — off-diagonal spatial z-z
A11: Γ^x_{xy} = Γ^x_{yx} | B11: =-Parameters!B24 | D11: −∂Φ/∂y — spatial cross-coupling (xy)
A12: Γ^x_{xz} = Γ^x_{zx} | B12: =-Parameters!B25 | D12: −∂Φ/∂z — spatial cross-coupling (xz)
A13: Γ^y_{tt} | B13: =Parameters!B24 | D13: ∂Φ/∂y — gravitoelectric acceleration (y)
A14: Γ^y_{yy} | B14: =-Parameters!B24 | D14: −∂Φ/∂y — self-diagonal spatial
A15: Γ^y_{xx} | B15: =Parameters!B24 | D15: ∂Φ/∂y — off-diagonal spatial x-x
A16: Γ^y_{zz} | B16: =Parameters!B24 | D16: ∂Φ/∂y — off-diagonal spatial z-z
A17: Γ^y_{xy} = Γ^y_{yx} | B17: =-Parameters!B23 | D17: −∂Φ/∂x — spatial cross-coupling (xy)
A18: Γ^y_{yz} = Γ^y_{zy} | B18: =-Parameters!B25 | D18: −∂Φ/∂z — spatial cross-coupling (yz)
A19: Γ^z_{tt} | B19: =Parameters!B25 | D19: ∂Φ/∂z — gravitoelectric acceleration (z)
A20: Γ^z_{zz} | B20: =-Parameters!B25 | D20: −∂Φ/∂z — self-diagonal spatial
A21: Γ^z_{xx} | B21: =Parameters!B25 | D21: ∂Φ/∂z — off-diagonal spatial x-x
A22: Γ^z_{yy} | B22: =Parameters!B25 | D22: ∂Φ/∂z — off-diagonal spatial y-y
A23: Γ^z_{xz} = Γ^z_{zx} | B23: =-Parameters!B23 | D23: −∂Φ/∂x — spatial cross-coupling (xz)
A24: Γ^z_{yz} = Γ^z_{zy} | B24: =-Parameters!B24 | D24: −∂Φ/∂y — spatial cross-coupling (yz)

Sheet Jacobian
A1: 10×10 Jacobian Matrix J_{ij} = ∂(dz_i/dτ)/∂z_j Evaluated at Circular Orbit (x₀,0,0) — TEGR Weak-Field Geodesic + Torsion Transport
A2: State vector z = (t, x, y, z, u^t, u^x, u^y, u^z, T_scalar, Ṫ) • All cells are Excel formulas referencing the Parameters sheet • Geometrized units G = c = 1
A3: Equation / Variable → | B3: ∂/∂t z₁=t | C3: ∂/∂x z₂=x | D3: ∂/∂y z₃=y | E3: ∂/∂z z₄=z | F3: ∂/∂u^t z₅=u^t | G3: ∂/∂u^x z₆=u^x | H3: ∂/∂u^y z₇=u^y | I3: ∂/∂u^z z₈=u^z | J3: ∂/∂T z₉=T | K3: ∂/∂Ṫ z₁₀=Ṫ
A4: f₁ = dt/dτ = u^t | B4: 0 | C4: 0 | D4: 0 | E4: 0 | F4: 1 | G4: 0 | H4: 0 | I4: 0 | J4: 0 | K4: 0
A5: f₂ = dx/dτ = u^x | B5: 0 | C5: 0 | D5: 0 | E5: 0 | F5: 0 | G5: 1 | H5: 0 | I5: 0 | J5: 0 | K5: 0
A6: f₃ = dy/dτ = u^y | B6: 0 | C6: 0 | D6: 0 | E6: 0 | F6: 0 | G6: 0 | H6: 1 | I6: 0 | J6: 0 | K6: 0
A7: f₄ = dz/dτ = u^z | B7: 0 | C7: 0 | D7: 0 | E7: 0 | F7: 0 | G7: 0 | H7: 0 | I7: 1 | J7: 0 | K7: 0
A8: f₅ = du^t/dτ | B8: 0 | C8: =-2*Parameters!B17*(Parameters!B26*Parameters!B18+Parameters!B29*Parameters!B19+Parameters!B30*Parameters!B20) | D8: =-2*Parameters!B17*(Parameters!B29*Parameters!B18+Parameters!B27*Parameters!B19+Parameters!B31*Parameters!B20) | E8: =-2*Parameters!B17*(Parameters!B30*Parameters!B18+Parameters!B31*Parameters!B19+Parameters!B28*Parameters!B20) | F8: =-2*(Parameters!B23*Parameters!B18+Parameters!B24*Parameters!B19+Parameters!B25*Parameters!B20) | G8: =-2*Parameters!B17*Parameters!B23 | H8: =-2*Parameters!B17*Parameters!B24 | I8: =-2*Parameters!B17*Parameters!B25 | J8: 0 | K8: 0
A9: f₆ = du^x/dτ | B9: 0 | C9: =-Parameters!B26*(Parameters!B17^2-Parameters!B18^2+Parameters!B19^2+Parameters!B20^2)+2*Parameters!B29*Parameters!B18*Parameters!B19+2*Parameters!B30*Parameters!B18*Parameters!B20 | D9: =-Parameters!B29*(Parameters!B17^2-Parameters!B18^2+Parameters!B19^2+Parameters!B20^2)+2*Parameters!B27*Parameters!B18*Parameters!B19+2*Parameters!B31*Parameters!B18*Parameters!B20 | E9: =-Parameters!B30*(Parameters!B17^2-Parameters!B18^2+Parameters!B19^2+Parameters!B20^2)+2*Parameters!B31*Parameters!B18*Parameters!B19+2*Parameters!B28*Parameters!B18*Parameters!B20 | F9: =-2*Parameters!B23*Parameters!B17 | G9: =2*Parameters!B23*Parameters!B18+2*Parameters!B24*Parameters!B19+2*Parameters!B25*Parameters!B20 | H9: =-2*Parameters!B23*Parameters!B19+2*Parameters!B24*Parameters!B18 | I9: =-2*Parameters!B23*Parameters!B20+2*Parameters!B25*Parameters!B18 | J9: 0 | K9: 0
A10: f₇ = du^y/dτ | B10: 0 | C10: =-Parameters!B29*(Parameters!B17^2+Parameters!B18^2-Parameters!B19^2+Parameters!B20^2)+2*Parameters!B26*Parameters!B18*Parameters!B19+2*Parameters!B30*Parameters!B19*Parameters!B20 | D10: =-Parameters!B27*(Parameters!B17^2+Parameters!B18^2-Parameters!B19^2+Parameters!B20^2)+2*Parameters!B29*Parameters!B18*Parameters!B19+2*Parameters!B31*Parameters!B19*Parameters!B20 | E10: =-Parameters!B31*(Parameters!B17^2+Parameters!B18^2-Parameters!B19^2+Parameters!B20^2)+2*Parameters!B30*Parameters!B18*Parameters!B19+2*Parameters!B28*Parameters!B19*Parameters!B20 | F10: =-2*Parameters!B24*Parameters!B17 | G10: =-2*Parameters!B24*Parameters!B18+2*Parameters!B23*Parameters!B19 | H10: =2*Parameters!B24*Parameters!B19+2*Parameters!B23*Parameters!B18+2*Parameters!B25*Parameters!B20 | I10: =-2*Parameters!B24*Parameters!B20+2*Parameters!B25*Parameters!B19 | J10: 0 | K10: 0
A11: f₈ = du^z/dτ | B11: 0 | C11: =-Parameters!B30*(Parameters!B17^2+Parameters!B18^2+Parameters!B19^2-Parameters!B20^2)+2*Parameters!B26*Parameters!B18*Parameters!B20+2*Parameters!B29*Parameters!B19*Parameters!B20 | D11: =-Parameters!B31*(Parameters!B17^2+Parameters!B18^2+Parameters!B19^2-Parameters!B20^2)+2*Parameters!B29*Parameters!B18*Parameters!B20+2*Parameters!B27*Parameters!B19*Parameters!B20 | E11: =-Parameters!B28*(Parameters!B17^2+Parameters!B18^2+Parameters!B19^2-Parameters!B20^2)+2*Parameters!B30*Parameters!B18*Parameters!B20+2*Parameters!B31*Parameters!B19*Parameters!B20 | F11: =-2*Parameters!B25*Parameters!B17 | G11: =-2*Parameters!B25*Parameters!B18+2*Parameters!B23*Parameters!B20 | H11: =-2*Parameters!B25*Parameters!B19+2*Parameters!B24*Parameters!B20 | I11: =2*Parameters!B25*Parameters!B20+2*Parameters!B23*Parameters!B18+2*Parameters!B24*Parameters!B19 | J11: 0 | K11: 0
A12: f₉ = dT/dτ = Ṫ | B12: 0 | C12: 0 | D12: 0 | E12: 0 | F12: 0 | G12: 0 | H12: 0 | I12: 0 | J12: 0 | K12: 1
A13: f₁₀ = d²T/dτ² | B13: 0 | C13: =Parameters!B45*Parameters!B18^2+Parameters!B48*Parameters!B19^2+Parameters!B49*Parameters!B20^2+2*Parameters!B46*Parameters!B18*Parameters!B19+2*Parameters!B47*Parameters!B18*Parameters!B20+Parameters!B38*Parameters!B52+Parameters!B41*Parameters!B53+Parameters!B42*Parameters!B54+Parameters!B35*C9+Parameters!B36*C10+Parameters!B37*C11 | D13: =(12*Parameters!B3*Parameters!B5*Parameters!B10*(35*Parameters!B9^2-5*Parameters!B13^2)/Parameters!B13^9)*Parameters!B18^2+(12*Parameters!B3*Parameters!B5*Parameters!B10*(35*Parameters!B10^2-17*Parameters!B13^2)/Parameters!B13^9)*Parameters!B19^2+(12*Parameters!B3*Parameters!B5*Parameters!B10*(35*Parameters!B11^2-5*Parameters!B13^2)/Parameters!B13^9)*Parameters!B20^2+2*(-60*Parameters!B3*Parameters!B5*Parameters!B10*(Parameters!B13^2-7*Parameters!B10^2)/Parameters!B13^9)*Parameters!B18*Parameters!B19+Parameters!B41*Parameters!B52+Parameters!B35*D9+Parameters!B39*Parameters!B53+Parameters!B36*D10+Parameters!B43*Parameters!B54+Parameters!B37*D11 | E13: =(12*Parameters!B3*Parameters!B5*Parameters!B11*(35*Parameters!B9^2-5*Parameters!B13^2)/Parameters!B13^9)*Parameters!B18^2+(12*Parameters!B3*Parameters!B5*Parameters!B11*(35*Parameters!B10^2-5*Parameters!B13^2)/Parameters!B13^9)*Parameters!B19^2+(12*Parameters!B3*Parameters!B5*Parameters!B11*(35*Parameters!B11^2-17*Parameters!B13^2)/Parameters!B13^9)*Parameters!B20^2+2*(-60*Parameters!B3*Parameters!B5*Parameters!B11*(Parameters!B13^2-7*Parameters!B11^2)/Parameters!B13^9)*Parameters!B18*Parameters!B20+Parameters!B42*Parameters!B52+Parameters!B35*E9+Parameters!B43*Parameters!B53+Parameters!B36*E10+Parameters!B40*Parameters!B54+Parameters!B37*E11 | F13: =Parameters!B35*F9+Parameters!B36*F10+Parameters!B37*F11 | G13: =2*Parameters!B38*Parameters!B18+2*Parameters!B41*Parameters!B19+2*Parameters!B42*Parameters!B20+Parameters!B35*G9+Parameters!B36*G10+Parameters!B37*G11 | H13: =2*Parameters!B39*Parameters!B19+2*Parameters!B41*Parameters!B18+2*Parameters!B43*Parameters!B20+Parameters!B35*H9+Parameters!B36*H10+Parameters!B37*H11 | I13: =2*Parameters!B40*Parameters!B20+2*Parameters!B42*Parameters!B18+2*Parameters!B43*Parameters!B19+Parameters!B35*I9+Parameters!B36*I10+Parameters!B37*I11 | J13: 0 | K13: 0

Sheet Analysis
A1: Jacobian Analysis — Trace, Norms, Block Structure, Conservation Checks
A2: Scalar Properties of the Jacobian Matrix J ∈ ℝ^{10×10}
A3: Tr(J) — Trace (sum of diagonal elements) | B3: =Jacobian!B4+Jacobian!C5+Jacobian!D6+Jacobian!E7+Jacobian!F8+Jacobian!G9+Jacobian!H10+Jacobian!I11+Jacobian!J12+Jacobian!K13 | C3: dimensionless | D3: For Hamiltonian systems Tr(J) = 0 (Liouville); non-zero here due to TEGR torsion coupling
A4: ‖J‖_F — Frobenius norm √(Σ J_ij²) | B4: =SQRT(SUMPRODUCT(Jacobian!B4:K13*Jacobian!B4:K13)) | C4: dimensionless | D4: Measures overall magnitude of the Jacobian (sensitivity)
A5: max|J_ij| — Maximum absolute entry | B5: =MAX(ABS(Jacobian!B4:K13)) | C5: dimensionless | D5: Largest Jacobian element (dominant coupling)
A6: Block Structure Analysis
A7: Position block Tr (rows 1–4, cols 1–4) | B7: =Jacobian!B4+Jacobian!C5+Jacobian!D6+Jacobian!E7 | C7: dimensionless | D7: Should be 0 (no coordinate self-coupling)
A8: Velocity block Tr (rows 5–8, cols 5–8) | B8: =Jacobian!F8+Jacobian!G9+Jacobian!H10+Jacobian!I11 | C8: dimensionless | D8: Geodesic self-damping; 0 in flat-space limit
A9: Torsion block Tr (rows 9–10, cols 9–10) | B9: =Jacobian!J12+Jacobian!K13 | C9: dimensionless | D9: Torsion subsystem trace
A10: Tidal Tensor Components (=Jacobian rows 6–8, cols 2–4 = ∂f_{x,y,z}/∂{x,y,z})
A11: K_xx = ∂(du^x/dτ)/∂x (radial tidal) | B11: =Jacobian!C9 | C11: 1/[m²] | D11: =2M/r₀³ for circular orbit at x₀=r₀ (centrifugal + tidal)
A12: K_yy = ∂(du^y/dτ)/∂y (transverse tidal) | B12: =Jacobian!D10 | C12: 1/[m²] | D12: =−M/r₀³ (restoring tidal in orbital direction)
A13: K_zz = ∂(du^z/dτ)/∂z (vertical tidal) | B13: =Jacobian!E11 | C13: 1/[m²] | D13: =−M/r₀³ (restoring tidal perpendicular to plane)
A14: Tr(K) = K_xx + K_yy + K_zz (should ≈ 0, Laplace eq.) | B14: =B11+B12+B13 | C14: 1/[m²] | D14: Tr(K) = 0 away from source: ∇²Φ = 0 (vacuum Poisson eq.)
A15: Orbital Frequency Cross-Check
A16: ω² (Newtonian) = GM/r₀³ = Φ_x/r₀² | B16: =Parameters!B3*Parameters!B5/Parameters!B13^3 | C16: 1/[m²] | D16: Newtonian orbital angular frequency squared
A17: Epicyclic freq² κ² ≈ 4ω² − ∂²Ω²/∂ln r · ω² | B17: =4*B16-3*B16 | C17: 1/[m²] | D17: For Keplerian orbit: κ² = ω² (confirmed by J₇₃ = −M/r₀³ = −ω²)
A18: Vertical freq² ν² = GM/r₀³ | B18: =Parameters!B3*Parameters!B5/Parameters!B13^3 | C18: 1/[m²] | D18: Oscillation frequency perpendicular to orbital plane; equals K_zz magnitude
A19: TEGR Torsion Coupling Strengths (Row 10 of Jacobian)
A20: J₁₀,₅ = ∂(d²T/dτ²)/∂u^t | B20: =Jacobian!F13 | C20: 1/[m³] | D20: Torsion acceleration sensitivity to u^t; = −2 T_x Φ_x u^t
A21: J₁₀,₇ = ∂(d²T/dτ²)/∂u^y (dominant torsion coupling) | B21: =Jacobian!H13 | C21: 1/[m³] | D21: =2 T_yy u^y + T_x J₆₇ — torsion response to tangential velocity
A22: J₁₀,₂ = ∂(d²T/dτ²)/∂x (tidal torsion gradient) | B22: =Jacobian!C13 | C22: 1/[m⁴] | D22: =(∂T_yy/∂x) u^y² + T_xx f₆ + T_x J₆₂
A23: Summary Table — Non-Zero Jacobian Elements at Default Evaluation Point
A24: Element J_{ij} | B24: Row i (equation) | C24: Col j (variable) | D24: Numerical Value | E24: Physical Interpretation
A25: J_{1,5} | B25: f₁=dt/dτ | C25: u^t | D25: =Jacobian!F4 | E25: =1 (identity coupling: dt/dτ = u^t)
A26: J_{2,6} | B26: f₂=dx/dτ | C26: u^x | D26: =Jacobian!G5 | E26: =1 (identity coupling: dx/dτ = u^x)
A27: J_{3,7} | B27: f₃=dy/dτ | C27: u^y | D27: =Jacobian!H6 | E27: =1 (identity coupling: dy/dτ = u^y)
A28: J_{4,8} | B28: f₄=dz/dτ | C28: u^z | D28: =Jacobian!I7 | E28: =1 (identity coupling: dz/dτ = u^z)
A29: J_{5,6} | B29: f₅=du^t/dτ | C29: u^x | D29: =Jacobian!G8 | E29: =−2γΦ_x (gravitomagnetic time dilation)
A30: J_{5,7} | B30: f₅=du^t/dτ | C30: u^y | D30: =Jacobian!H8 | E30: =−2γΦ_y = 0 (zero by symmetry at y₀=0)
A31: J_{6,2} | B31: f₆=du^x/dτ | C31: x | D31: =Jacobian!C9 | E31: Tidal: −Φ_xx(γ²+γ²v²) = 2M(1+v²)γ²/r₀³
A32: J_{6,5} | B32: f₆=du^x/dτ | C32: u^t | D32: =Jacobian!F9 | E32: =−2Φ_x u^t (gravitoelectric force coupling)
A33: J_{6,7} | B33: f₆=du^x/dτ | C33: u^y | D33: =Jacobian!H9 | E33: =−2Φ_x u^y (Coriolis-like term)
A34: J_{7,3} | B34: f₇=du^y/dτ | C34: y | D34: =Jacobian!D10 | E34: Tidal: −Φ_yy(γ²−γ²v²) = −M/r₀³ (restoring)
A35: J_{7,6} | B35: f₇=du^y/dτ | C35: u^x | D35: =Jacobian!G10 | E35: =2Φ_x u^y (Coriolis-like term)
A36: J_{8,4} | B36: f₈=du^z/dτ | C36: z | D36: =Jacobian!E11 | E36: Tidal: −Φ_zz(γ²+γ²v²) = −M(1+v²)γ²/r₀³
A37: J_{9,10} | B37: f₉=dT/dτ | C37: Ṫ | D37: =Jacobian!K12 | E37: =1 (torsion rate kinematic equation)
A38: J_{10,2} | B38: f₁₀=d²T/dτ² | C38: x | D38: =Jacobian!C13 | E38: Torsion-tidal coupling along x
A39: J_{10,5} | B39: f₁₀=d²T/dτ² | C39: u^t | D39: =Jacobian!F13 | E39: =−2 T_x Φ_x u^t (time-dilation torsion)
A40: J_{10,7} | B40: f₁₀=d²T/dτ² | C40: u^y | D40: =Jacobian!H13 | E40: =2T_yy u^y + T_x J₆₇ (dominant TEGR coupling)
